# Deep crypt descent and north promenade into the shifting labyrinth.
# connector: descent->maze
# Eighteen stone stair slices descend from the ruined nave to dungeon floor y=-18.
fill ~-4 ~-1 ~10 ~4 ~4 ~10 minecraft:stone_bricks
fill ~-3 ~ ~10 ~3 ~3 ~10 minecraft:air
fill ~-2 ~-1 ~10 ~2 ~-1 ~10 minecraft:stone_brick_stairs[facing=south,half=bottom,shape=straight,waterlogged=false]
fill ~-4 ~-2 ~11 ~4 ~3 ~11 minecraft:stone_bricks
fill ~-3 ~-1 ~11 ~3 ~2 ~11 minecraft:air
fill ~-2 ~-2 ~11 ~2 ~-2 ~11 minecraft:stone_brick_stairs[facing=south,half=bottom,shape=straight,waterlogged=false]
fill ~-4 ~-3 ~12 ~4 ~2 ~12 minecraft:stone_bricks
fill ~-3 ~-2 ~12 ~3 ~1 ~12 minecraft:air
fill ~-2 ~-3 ~12 ~2 ~-3 ~12 minecraft:stone_brick_stairs[facing=south,half=bottom,shape=straight,waterlogged=false]
fill ~-4 ~-4 ~13 ~4 ~1 ~13 minecraft:stone_bricks
fill ~-3 ~-3 ~13 ~3 ~ ~13 minecraft:air
fill ~-2 ~-4 ~13 ~2 ~-4 ~13 minecraft:stone_brick_stairs[facing=south,half=bottom,shape=straight,waterlogged=false]
setblock ~-3 ~-1 ~13 minecraft:soul_lantern[hanging=true,waterlogged=false]
fill ~-4 ~-5 ~14 ~4 ~ ~14 minecraft:stone_bricks
fill ~-3 ~-4 ~14 ~3 ~-1 ~14 minecraft:air
fill ~-2 ~-5 ~14 ~2 ~-5 ~14 minecraft:stone_brick_stairs[facing=south,half=bottom,shape=straight,waterlogged=false]
fill ~-4 ~-6 ~15 ~4 ~-1 ~15 minecraft:stone_bricks
fill ~-3 ~-5 ~15 ~3 ~-2 ~15 minecraft:air
fill ~-2 ~-6 ~15 ~2 ~-6 ~15 minecraft:stone_brick_stairs[facing=south,half=bottom,shape=straight,waterlogged=false]
fill ~-4 ~-7 ~16 ~4 ~-2 ~16 minecraft:stone_bricks
fill ~-3 ~-6 ~16 ~3 ~-3 ~16 minecraft:air
fill ~-2 ~-7 ~16 ~2 ~-7 ~16 minecraft:stone_brick_stairs[facing=south,half=bottom,shape=straight,waterlogged=false]
fill ~-4 ~-8 ~17 ~4 ~-3 ~17 minecraft:stone_bricks
fill ~-3 ~-7 ~17 ~3 ~-4 ~17 minecraft:air
fill ~-2 ~-8 ~17 ~2 ~-8 ~17 minecraft:stone_brick_stairs[facing=south,half=bottom,shape=straight,waterlogged=false]
setblock ~-3 ~-5 ~17 minecraft:soul_lantern[hanging=true,waterlogged=false]
fill ~-4 ~-9 ~18 ~4 ~-4 ~18 minecraft:stone_bricks
fill ~-3 ~-8 ~18 ~3 ~-5 ~18 minecraft:air
fill ~-2 ~-9 ~18 ~2 ~-9 ~18 minecraft:stone_brick_stairs[facing=south,half=bottom,shape=straight,waterlogged=false]
fill ~-4 ~-10 ~19 ~4 ~-5 ~19 minecraft:stone_bricks
fill ~-3 ~-9 ~19 ~3 ~-6 ~19 minecraft:air
fill ~-2 ~-10 ~19 ~2 ~-10 ~19 minecraft:stone_brick_stairs[facing=south,half=bottom,shape=straight,waterlogged=false]
fill ~-4 ~-11 ~20 ~4 ~-6 ~20 minecraft:stone_bricks
fill ~-3 ~-10 ~20 ~3 ~-7 ~20 minecraft:air
fill ~-2 ~-11 ~20 ~2 ~-11 ~20 minecraft:stone_brick_stairs[facing=south,half=bottom,shape=straight,waterlogged=false]
fill ~-4 ~-12 ~21 ~4 ~-7 ~21 minecraft:stone_bricks
fill ~-3 ~-11 ~21 ~3 ~-8 ~21 minecraft:air
fill ~-2 ~-12 ~21 ~2 ~-12 ~21 minecraft:stone_brick_stairs[facing=south,half=bottom,shape=straight,waterlogged=false]
setblock ~-3 ~-9 ~21 minecraft:soul_lantern[hanging=true,waterlogged=false]
fill ~-4 ~-13 ~22 ~4 ~-8 ~22 minecraft:stone_bricks
fill ~-3 ~-12 ~22 ~3 ~-9 ~22 minecraft:air
fill ~-2 ~-13 ~22 ~2 ~-13 ~22 minecraft:stone_brick_stairs[facing=south,half=bottom,shape=straight,waterlogged=false]
fill ~-4 ~-14 ~23 ~4 ~-9 ~23 minecraft:stone_bricks
fill ~-3 ~-13 ~23 ~3 ~-10 ~23 minecraft:air
fill ~-2 ~-14 ~23 ~2 ~-14 ~23 minecraft:stone_brick_stairs[facing=south,half=bottom,shape=straight,waterlogged=false]
fill ~-4 ~-15 ~24 ~4 ~-10 ~24 minecraft:stone_bricks
fill ~-3 ~-14 ~24 ~3 ~-11 ~24 minecraft:air
fill ~-2 ~-15 ~24 ~2 ~-15 ~24 minecraft:stone_brick_stairs[facing=south,half=bottom,shape=straight,waterlogged=false]
fill ~-4 ~-16 ~25 ~4 ~-11 ~25 minecraft:stone_bricks
fill ~-3 ~-15 ~25 ~3 ~-12 ~25 minecraft:air
fill ~-2 ~-16 ~25 ~2 ~-16 ~25 minecraft:stone_brick_stairs[facing=south,half=bottom,shape=straight,waterlogged=false]
setblock ~-3 ~-13 ~25 minecraft:soul_lantern[hanging=true,waterlogged=false]
fill ~-4 ~-17 ~26 ~4 ~-12 ~26 minecraft:stone_bricks
fill ~-3 ~-16 ~26 ~3 ~-13 ~26 minecraft:air
fill ~-2 ~-17 ~26 ~2 ~-17 ~26 minecraft:stone_brick_stairs[facing=south,half=bottom,shape=straight,waterlogged=false]
fill ~-4 ~-18 ~27 ~4 ~-13 ~27 minecraft:stone_bricks
fill ~-3 ~-17 ~27 ~3 ~-14 ~27 minecraft:air
fill ~-2 ~-18 ~27 ~2 ~-18 ~27 minecraft:stone_brick_stairs[facing=south,half=bottom,shape=straight,waterlogged=false]
# Lower turning chamber and roofed promenade run outside the maze's north wall.
fill ~-6 ~-18 ~20 ~6 ~-7 ~32 minecraft:stone_bricks
fill ~-5 ~-17 ~21 ~5 ~-9 ~31 minecraft:air
fill ~-5 ~-18 ~21 ~5 ~-18 ~31 minecraft:polished_deepslate
fill ~-48 ~-18 ~19 ~4 ~-7 ~25 minecraft:stone_bricks
fill ~-47 ~-17 ~20 ~3 ~-9 ~24 minecraft:air
fill ~-47 ~-18 ~20 ~3 ~-18 ~24 minecraft:polished_deepslate
fill ~-47 ~-8 ~20 ~3 ~-8 ~24 minecraft:stone_brick_slab[type=top,waterlogged=false]
# Procession ribs and lights make the long approach intentional rather than empty.
fill ~-44 ~-17 ~20 ~-43 ~-10 ~24 minecraft:chiseled_stone_bricks
fill ~-36 ~-17 ~20 ~-35 ~-10 ~24 minecraft:cracked_stone_bricks
fill ~-28 ~-17 ~20 ~-27 ~-10 ~24 minecraft:chiseled_stone_bricks
fill ~-20 ~-17 ~20 ~-19 ~-10 ~24 minecraft:mossy_stone_bricks
fill ~-12 ~-17 ~20 ~-11 ~-10 ~24 minecraft:chiseled_stone_bricks
fill ~-4 ~-17 ~20 ~-3 ~-10 ~24 minecraft:cracked_stone_bricks
setblock ~-40 ~-9 ~22 minecraft:soul_lantern[hanging=true,waterlogged=false]
setblock ~-24 ~-9 ~22 minecraft:soul_lantern[hanging=true,waterlogged=false]
setblock ~-8 ~-9 ~22 minecraft:soul_lantern[hanging=true,waterlogged=false]
# West-end turn cuts through the hidden containment and opens only the fixed entrance cell (0,0).
fill ~-48 ~-18 ~22 ~-40 ~-7 ~30 minecraft:stone_bricks
fill ~-47 ~-17 ~23 ~-41 ~-9 ~30 minecraft:air
fill ~-47 ~-18 ~23 ~-41 ~-18 ~30 minecraft:cracked_deepslate_tiles
fill ~-45 ~-17 ~25 ~-43 ~-10 ~29 minecraft:air
fill ~-45 ~-18 ~25 ~-43 ~-18 ~30 minecraft:polished_deepslate
setblock ~-44 ~-9 ~27 minecraft:soul_lantern[hanging=true,waterlogged=false]
