# Six authored navigation districts. Details stay inside cell interiors so mutable portals remain unobstructed.
# Serpent-column gallery
fill ~-32 ~-18 ~35 ~-14 ~-18 ~39 minecraft:deepslate_tiles
fill ~-31 ~-17 ~35 ~-30 ~-10 ~36 minecraft:chiseled_stone_bricks
fill ~-18 ~-17 ~38 ~-17 ~-10 ~39 minecraft:chiseled_stone_bricks
setblock ~-29 ~-9 ~37 minecraft:soul_lantern[hanging=true,waterlogged=false]
setblock ~-22 ~-9 ~37 minecraft:soul_lantern[hanging=true,waterlogged=false]
setblock ~-15 ~-9 ~37 minecraft:soul_lantern[hanging=true,waterlogged=false]
# Moss/root crypt
fill ~-33 ~-18 ~49 ~-22 ~-18 ~58 minecraft:mossy_stone_bricks
setblock ~-30 ~-17 ~51 minecraft:moss_carpet
setblock ~-26 ~-17 ~55 minecraft:moss_carpet
setblock ~-23 ~-17 ~52 minecraft:moss_carpet
fill ~-32 ~-17 ~57 ~-31 ~-12 ~58 minecraft:mossy_cobblestone
setblock ~-27 ~-9 ~54 minecraft:chain[axis=y,waterlogged=false]
# Lava-cracked district
fill ~-33 ~-18 ~83 ~-20 ~-18 ~91 minecraft:cracked_deepslate_tiles
fill ~-31 ~-18 ~86 ~-24 ~-18 ~86 minecraft:magma_block
fill ~-31 ~-17 ~84 ~-31 ~-15 ~88 minecraft:polished_blackstone_bricks
setblock ~-31 ~-16 ~86 minecraft:lava
setblock ~-30 ~-16 ~86 minecraft:iron_bars
setblock ~-24 ~-17 ~89 minecraft:soul_fire
# Petrified expedition
fill ~10 ~-18 ~90 ~18 ~-18 ~97 minecraft:cobbled_deepslate
setblock ~12 ~-17 ~92 minecraft:skeleton_skull[rotation=4]
setblock ~16 ~-17 ~95 minecraft:wither_skeleton_skull[rotation=12]
setblock ~13 ~-17 ~96 minecraft:cobweb
setblock ~17 ~-17 ~91 minecraft:cobweb
setblock ~14 ~-17 ~93 minecraft:soul_campfire[lit=true,signal_fire=false,waterlogged=false]
# Tall central junction
fill ~-6 ~-9 ~68 ~2 ~-2 ~76 minecraft:air
fill ~-5 ~-17 ~69 ~-4 ~-4 ~70 minecraft:chiseled_deepslate
fill ~0 ~-17 ~69 ~1 ~-4 ~70 minecraft:chiseled_deepslate
fill ~-5 ~-17 ~74 ~-4 ~-4 ~75 minecraft:chiseled_deepslate
fill ~0 ~-17 ~74 ~1 ~-4 ~75 minecraft:chiseled_deepslate
fill ~-5 ~-3 ~69 ~1 ~-3 ~75 minecraft:stone_brick_stairs[facing=north,half=top,shape=straight,waterlogged=false]
fill ~-4 ~-2 ~70 ~0 ~-2 ~74 minecraft:stone_brick_slab[type=top,waterlogged=false]
setblock ~-2 ~-4 ~72 minecraft:chain[axis=y,waterlogged=false]
setblock ~-2 ~-5 ~72 minecraft:soul_lantern[hanging=true,waterlogged=false]
# Gorgon-relief corridor
fill ~23 ~-17 ~97 ~30 ~-11 ~103 minecraft:chiseled_stone_bricks
fill ~24 ~-16 ~97 ~29 ~-12 ~97 minecraft:oxidized_cut_copper
setblock ~25 ~-14 ~96 minecraft:green_glazed_terracotta[facing=south]
setblock ~28 ~-14 ~96 minecraft:green_glazed_terracotta[facing=south]
setblock ~26 ~-12 ~96 minecraft:chiseled_stone_bricks
setblock ~27 ~-12 ~96 minecraft:chiseled_stone_bricks
